Workbook

Sheet Resumen
A1: RESUMEN — TOTAL NETO COBRADO POR DÍA (TODOS LOS PROCESADORES)
A3: Suma automáticamente lo que se liquida cada día (ya neto de comisión y refund) en Adyen, Nuvei, Shift4 y Paysafe. | H3: CIERRE SEMANAL — para Temporary Restriction (Ventas − Fees = Venta Neta · Collected · Retenido)
H4: Por semana ISO y procesador. Venta Neta = Ventas − Fees (ventas limpias de comisiones). Retenido = neto vendido hasta el domingo y aún sin liquidar.
A5: Fecha | B5: Adyen | C5: Nuvei | D5: Shift4 | E5: Paysafe | F5: Total Neto del día | H5: Año | I5: Semana | J5: Fechas | K5: Adyen | P5: Nuvei | U5: Shift4 | Z5: Paysafe | AE5: TOTAL
A6: 45926 | B6: =SUMIFS('Adyen'!$E$11:$E$207,'Adyen'!$G$11:$G$207,$A6) | C6: =SUMIFS('Nuvei'!$E$11:$E$296,'Nuvei'!$G$11:$G$296,$A6) | D6: =SUMIFS('Shift4'!$E$11:$E$116,'Shift4'!$G$11:$G$116,$A6) | E6: =SUMIFS('Paysafe'!$E$11:$E$44,'Paysafe'!$G$11:$G$44,$A6) | F6: =SUM(B6:E6) | K6: Ventas | L6: Fees | M6: Venta Neta | N6: Collected | O6: Retenido | P6: Ventas | Q6: Fees | R6: Venta Neta | S6: Collected | T6: Retenido | U6: Ventas | V6: Fees | W6: Venta Neta | X6: Collected | Y6: Retenido | Z6: Ventas | AA6: Fees | AB6: Venta Neta | AC6: Collected | AD6: Retenido | AE6: Ventas | AF6: Fees | AG6: Venta Neta | AH6: Collected | AI6: Retenido
A7: 45927 | B7: =SUMIFS('Adyen'!$E$11:$E$207,'Adyen'!$G$11:$G$207,$A7) | C7: =SUMIFS('Nuvei'!$E$11:$E$296,'Nuvei'!$G$11:$G$296,$A7) | D7: =SUMIFS('Shift4'!$E$11:$E$116,'Shift4'!$G$11:$G$116,$A7) | E7: =SUMIFS('Paysafe'!$E$11:$E$44,'Paysafe'!$G$11:$G$44,$A7) | F7: =SUM(B7:E7) | H7: 2025 | I7: W39 | J7: 22/09 - 28/09/2025 | K7: =SUMIFS('Adyen'!$B$11:$B$207,'Adyen'!$A$11:$A$207,">="&$AN7,'Adyen'!$A$11:$A$207,"<="&$AO7) | L7: =SUMIFS('Adyen'!$C$11:$C$207,'Adyen'!$A$11:$A$207,">="&$AN7,'Adyen'!$A$11:$A$207,"<="&$AO7) | M7: =K7-L7 | N7: =SUMIFS('Adyen'!$E$11:$E$207,'Adyen'!$G$11:$G$207,">="&$AN7,'Adyen'!$G$11:$G$207,"<="&$AO7) | O7: =SUMIFS('Adyen'!$E$11:$E$207,'Adyen'!$A$11:$A$207,"<="&$AO7,'Adyen'!$G$11:$G$207,">"&$AO7) | P7: =SUMIFS('Nuvei'!$B$11:$B$296,'Nuvei'!$A$11:$A$296,">="&$AN7,'Nuvei'!$A$11:$A$296,"<="&$AO7) | Q7: =SUMIFS('Nuvei'!$C$11:$C$296,'Nuvei'!$A$11:$A$296,">="&$AN7,'Nuvei'!$A$11:$A$296,"<="&$AO7) | R7: =P7-Q7 | S7: =SUMIFS('Nuvei'!$E$11:$E$296,'Nuvei'!$G$11:$G$296,">="&$AN7,'Nuvei'!$G$11:$G$296,"<="&$AO7) | T7: =SUMIFS('Nuvei'!$E$11:$E$296,'Nuvei'!$A$11:$A$296,"<="&$AO7,'Nuvei'!$G$11:$G$296,">"&$AO7) | U7: =SUMIFS('Shift4'!$B$11:$B$116,'Shift4'!$A$11:$A$116,">="&$AN7,'Shift4'!$A$11:$A$116,"<="&$AO7) | V7: =SUMIFS('Shift4'!$C$11:$C$116,'Shift4'!$A$11:$A$116,">="&$AN7,'Shift4'!$A$11:$A$116,"<="&$AO7) | W7: =U7-V7 | X7: =SUMIFS('Shift4'!$E$11:$E$116,'Shift4'!$G$11:$G$116,">="&$AN7,'Shift4'!$G$11:$G$116,"<="&$AO7) | Y7: =SUMIFS('Shift4'!$E$11:$E$116,'Shift4'!$A$11:$A$116,"<="&$AO7,'Shift4'!$G$11:$G$116,">"&$AO7) | Z7: =SUMIFS('Paysafe'!$B$11:$B$44,'Paysafe'!$A$11:$A$44,">="&$AN7,'Paysafe'!$A$11:$A$44,"<="&$AO7) | AA7: =SUMIFS('Paysafe'!$C$11:$C$44,'Paysafe'!$A$11:$A$44,">="&$AN7,'Paysafe'!$A$11:$A$44,"<="&$AO7) | AB7: =Z7-AA7 | AC7: =SUMIFS('Paysafe'!$E$11:$E$44,'Paysafe'!$G$11:$G$44,">="&$AN7,'Paysafe'!$G$11:$G$44,"<="&$AO7) | AD7: =SUMIFS('Paysafe'!$E$11:$E$44,'Paysafe'!$A$11:$A$44,"<="&$AO7,'Paysafe'!$G$11:$G$44,">"&$AO7) | AE7: =K7+P7+U7+Z7 | AF7: =L7+Q7+V7+AA7 | AG7: =M7+R7+W7+AB7 | AH7: =N7+S7+X7+AC7 | AI7: =O7+T7+Y7+AD7 | AN7: 45922 | AO7: 45928
A8: 45928 | B8: =SUMIFS('Adyen'!$E$11:$E$207,'Adyen'!$G$11:$G$207,$A8) | C8: =SUMIFS('Nuvei'!$E$11:$E$296,'Nuvei'!$G$11:$G$296,$A8) | D8: =SUMIFS('Shift4'!$E$11:$E$116,'Shift4'!$G$11:$G$116,$A8) | E8: =SUMIFS('Paysafe'!$E$11:$E$44,'Paysafe'!$G$11:$G$44,$A8) | F8: =SUM(B8:E8) | H8: 2025 | I8: W40 | J8: 29/09 - 05/10/2025 | K8: =SUMIFS('Adyen'!$B$11:$B$207,'Adyen'!$A$11:$A$207,">="&$AN8,'Adyen'!$A$11:$A$207,"<="&$AO8) | L8: =SUMIFS('Adyen'!$C$11:$C$207,'Adyen'!$A$11:$A$207,">="&$AN8,'Adyen'!$A$11:$A$207,"<="&$AO8) | M8: =K8-L8 | N8: =SUMIFS('Adyen'!$E$11:$E$207,'Adyen'!$G$11:$G$207,">="&$AN8,'Adyen'!$G$11:$G$207,"<="&$AO8) | O8: =SUMIFS('Adyen'!$E$11:$E$207,'Adyen'!$A$11:$A$207,"<="&$AO8,'Adyen'!$G$11:$G$207,">"&$AO8) | P8: =SUMIFS('Nuvei'!$B$11:$B$296,'Nuvei'!$A$11:$A$296,">="&$AN8,'Nuvei'!$A$11:$A$296,"<="&$AO8) | Q8: =SUMIFS('Nuvei'!$C$11:$C$296,'Nuvei'!$A$11:$A$296,">="&$AN8,'Nuvei'!$A$11:$A$296,"<="&$AO8) | R8: =P8-Q8 | S8: =SUMIFS('Nuvei'!$E$11:$E$296,'Nuvei'!$G$11:$G$296,">="&$AN8,'Nuvei'!$G$11:$G$296,"<="&$AO8) | T8: =SUMIFS('Nuvei'!$E$11:$E$296,'Nuvei'!$A$11:$A$296,"<="&$AO8,'Nuvei'!$G$11:$G$296,">"&$AO8) | U8: =SUMIFS('Shift4'!$B$11:$B$116,'Shift4'!$A$11:$A$116,">="&$AN8,'Shift4'!$A$11:$A$116,"<="&$AO8) | V8: =SUMIFS('Shift4'!$C$11:$C$116,'Shift4'!$A$11:$A$116,">="&$AN8,'Shift4'!$A$11:$A$116,"<="&$AO8) | W8: =U8-V8 | X8: =SUMIFS('Shift4'!$E$11:$E$116,'Shift4'!$G$11:$G$116,">="&$AN8,'Shift4'!$G$11:$G$116,"<="&$AO8) | Y8: =SUMIFS('Shift4'!$E$11:$E$116,'Shift4'!$A$11:$A$116,"<="&$AO8,'Shift4'!$G$11:$G$116,">"&$AO8) | Z8: =SUMIFS('Paysafe'!$B$11:$B$44,'Paysafe'!$A$11:$A$44,">="&$AN8,'Paysafe'!$A$11:$A$44,"<="&$AO8) | AA8: =SUMIFS('Paysafe'!$C$11:$C$44,'Paysafe'!$A$11:$A$44,">="&$AN8,'Paysafe'!$A$11:$A$44,"<="&$AO8) | AB8: =Z8-AA8 | AC8: =SUMIFS('Paysafe'!$E$11:$E$44,'Paysafe'!$G$11:$G$44,">="&$AN8,'Paysafe'!$G$11:$G$44,"<="&$AO8) | AD8: =SUMIFS('Paysafe'!$E$11:$E$44,'Paysafe'!$A$11:$A$44,"<="&$AO8,'Paysafe'!$G$11:$G$44,">"&$AO8) | AE8: =K8+P8+U8+Z8 | AF8: =L8+Q8+V8+AA8 | AG8: =M8+R8+W8+AB8 | AH8: =N8+S8+X8+AC8 | AI8: =O8+T8+Y8+AD8 | AN8: 45929 | AO8: 45935
A9: 45929 | B9: =SUMIFS('Adyen'!$E$11:$E$207,'Adyen'!$G$11:$G$207,$A9) | C9: =SUMIFS('Nuvei'!$E$11:$E$296,'Nuvei'!$G$11:$G$296,$A9) | D9: =SUMIFS('Shift4'!$E$11:$E$116,'Shift4'!$G$11:$G$116,$A9) | E9: =SUMIFS('Paysafe'!$E$11:$E$44,'Paysafe'!$G$11:$G$44,$A9) | F9: =SUM(B9:E9) | H9: 2025 | I9: W41 | J9: 06/10 - 12/10/2025 | K9: =SUMIFS('Adyen'!$B$11:$B$207,'Adyen'!$A$11:$A$207,">="&$AN9,'Adyen'!$A$11:$A$207,"<="&$AO9) | L9: =SUMIFS('Adyen'!$C$11:$C$207,'Adyen'!$A$11:$A$207,">="&$AN9,'Adyen'!$A$11:$A$207,"<="&$AO9) | M9: =K9-L9 | N9: =SUMIFS('Adyen'!$E$11:$E$207,'Adyen'!$G$11:$G$207,">="&$AN9,'Adyen'!$G$11:$G$207,"<="&$AO9) | O9: =SUMIFS('Adyen'!$E$11:$E$207,'Adyen'!$A$11:$A$207,"<="&$AO9,'Adyen'!$G$11:$G$207,">"&$AO9) | P9: =SUMIFS('Nuvei'!$B$11:$B$296,'Nuvei'!$A$11:$A$296,">="&$AN9,'Nuvei'!$A$11:$A$296,"<="&$AO9) | Q9: =SUMIFS('Nuvei'!$C$11:$C$296,'Nuvei'!$A$11:$A$296,">="&$AN9,'Nuvei'!$A$11:$A$296,"<="&$AO9) | R9: =P9-Q9 | S9: =SUMIFS('Nuvei'!$E$11:$E$296,'Nuvei'!$G$11:$G$296,">="&$AN9,'Nuvei'!$G$11:$G$296,"<="&$AO9) | T9: =SUMIFS('Nuvei'!$E$11:$E$296,'Nuvei'!$A$11:$A$296,"<="&$AO9,'Nuvei'!$G$11:$G$296,">"&$AO9) | U9: =SUMIFS('Shift4'!$B$11:$B$116,'Shift4'!$A$11:$A$116,">="&$AN9,'Shift4'!$A$11:$A$116,"<="&$AO9) | V9: =SUMIFS('Shift4'!$C$11:$C$116,'Shift4'!$A$11:$A$116,">="&$AN9,'Shift4'!$A$11:$A$116,"<="&$AO9) | W9: =U9-V9 | X9: =SUMIFS('Shift4'!$E$11:$E$116,'Shift4'!$G$11:$G$116,">="&$AN9,'Shift4'!$G$11:$G$116,"<="&$AO9) | Y9: =SUMIFS('Shift4'!$E$11:$E$116,'Shift4'!$A$11:$A$116,"<="&$AO9,'Shift4'!$G$11:$G$116,">"&$AO9) | Z9: =SUMIFS('Paysafe'!$B$11:$B$44,'Paysafe'!$A$11:$A$44,">="&$AN9,'Paysafe'!$A$11:$A$44,"<="&$AO9) | AA9: =SUMIFS('Paysafe'!$C$11:$C$44,'Paysafe'!$A$11:$A$44,">="&$AN9,'Paysafe'!$A$11:$A$44,"<="&$AO9) | AB9: =Z9-AA9 | AC9: =SUMIFS('Paysafe'!$E$11:$E$44,'Paysafe'!$G$11:$G$44,">="&$AN9,'Paysafe'!$G$11:$G$44,"<="&$AO9) | AD9: =SUMIFS('Paysafe'!$E$11:$E$44,'Paysafe'!$A$11:$A$44,"<="&$AO9,'Paysafe'!$G$11:$G$44,">"&$AO9) | AE9: =K9+P9+U9+Z9 | AF9: =L9+Q9+V9+AA9 | AG9: =M9+R9+W9+AB9 | AH9: =N9+S9+X9+AC9 | AI9: =O9+T9+Y9+AD9 | AN9: 45936 | AO9: 45942
A10: 45930 | B10: =SUMIFS('Adyen'!$E$11:$E$207,'Adyen'!$G$11:$G$207,$A10) | C10: =SUMIFS('Nuvei'!$E$11:$E$296,'Nuvei'!$G$11:$G$296,$A10) | D10: =SUMIFS('Shift4'!$E$11:$E$116,'Shift4'!$G$11:$G$116,$A10) | E10: =SUMIFS('Paysafe'!$E$11:$E$44,'Paysafe'!$G$11:$G$44,$A10) | F10: =SUM(B10:E10) | H10: 2025 | I10: W42 | J10: 13/10 - 19/10/2025 | K10: =SUMIFS('Adyen'!$B$11:$B$207,'Adyen'!$A$11:$A$207,">="&$AN10,'Adyen'!$A$11:$A$207,"<="&$AO10) | L10: =SUMIFS('Adyen'!$C$11:$C$207,'Adyen'!$A$11:$A$207,">="&$AN10,'Adyen'!$A$11:$A$207,"<="&$AO10) | M10: =K10-L10 | N10: =SUMIFS('Adyen'!$E$11:$E$207,'Adyen'!$G$11:$G$207,">="&$AN10,'Adyen'!$G$11:$G$207,"<="&$AO10) | O10: =SUMIFS('Adyen'!$E$11:$E$207,'Adyen'!$A$11:$A$207,"<="&$AO10,'Adyen'!$G$11:$G$207,">"&$AO10) | P10: =SUMIFS('Nuvei'!$B$11:$B$296,'Nuvei'!$A$11:$A$296,">="&$AN10,'Nuvei'!$A$11:$A$296,"<="&$AO10) | Q10: =SUMIFS('Nuvei'!$C$11:$C$296,'Nuvei'!$A$11:$A$296,">="&$AN10,'Nuvei'!$A$11:$A$296,"<="&$AO10) | R10: =P10-Q10 | S10: =SUMIFS('Nuvei'!$E$11:$E$296,'Nuvei'!$G$11:$G$296,">="&$AN10,'Nuvei'!$G$11:$G$296,"<="&$AO10) | T10: =SUMIFS('Nuvei'!$E$11:$E$296,'Nuvei'!$A$11:$A$296,"<="&$AO10,'Nuvei'!$G$11:$G$296,">"&$AO10) | U10: =SUMIFS('Shift4'!$B$11:$B$116,'Shift4'!$A$11:$A$116,">="&$AN10,'Shift4'!$A$11:$A$116,"<="&$AO10) | V10: =SUMIFS('Shift4'!$C$11:$C$116,'Shift4'!$A$11:$A$116,">="&$AN10,'Shift4'!$A$11:$A$116,"<="&$AO10) | W10: =U10-V10 | X10: =SUMIFS('Shift4'!$E$11:$E$116,'Shift4'!$G$11:$G$116,">="&$AN10,'Shift4'!$G$11:$G$116,"<="&$AO10) | Y10: =SUMIFS('Shift4'!$E$11:$E$116,'Shift4'!$A$11:$A$116,"<="&$AO10,'Shift4'!$G$11:$G$116,">"&$AO10) | Z10: =SUMIFS('Paysafe'!$B$11:$B$44,'Paysafe'!$A$11:$A$44,">="&$AN10,'Paysafe'!$A$11:$A$44,"<="&$AO10) | AA10: =SUMIFS('Paysafe'!$C$11:$C$44,'Paysafe'!$A$11:$A$44,">="&$AN10,'Paysafe'!$A$11:$A$44,"<="&$AO10) | AB10: =Z10-AA10 | AC10: =SUMIFS('Paysafe'!$E$11:$E$44,'Paysafe'!$G$11:$G$44,">="&$AN10,'Paysafe'!$G$11:$G$44,"<="&$AO10) | AD10: =SUMIFS('Paysafe'!$E$11:$E$44,'Paysafe'!$A$11:$A$44,"<="&$AO10,'Paysafe'!$G$11:$G$44,">"&$AO10) | AE10: =K10+P10+U10+Z10 | AF10: =L10+Q10+V10+AA10 | AG10: =M10+R10+W10+AB10 | AH10: =N10+S10+X10+AC10 | AI10: =O10+T10+Y10+AD10 | AN10: 45943 | AO10: 45949
A11: 45931 | B11: =SUMIFS('Adyen'!$E$11:$E$207,'Adyen'!$G$11:$G$207,$A11) | C11: =SUMIFS('Nuvei'!$E$11:$E$296,'Nuvei'!$G$11:$G$296,$A11) | D11: =SUMIFS('Shift4'!$E$11:$E$116,'Shift4'!$G$11:$G$116,$A11) | E11: =SUMIFS('Paysafe'!$E$11:$E$44,'Paysafe'!$G$11:$G$44,$A11) | F11: =SUM(B11:E11) | H11: 2025 | I11: W43 | J11: 20/10 - 26/10/2025 | K11: =SUMIFS('Adyen'!$B$11:$B$207,'Adyen'!$A$11:$A$207,">="&$AN11,'Adyen'!$A$11:$A$207,"<="&$AO11) | L11: =SUMIFS('Adyen'!$C$11:$C$207,'Adyen'!$A$11:$A$207,">="&$AN11,'Adyen'!$A$11:$A$207,"<="&$AO11) | M11: =K11-L11 | N11: =SUMIFS('Adyen'!$E$11:$E$207,'Adyen'!$G$11:$G$207,">="&$AN11,'Adyen'!$G$11:$G$207,"<="&$AO11) | O11: =SUMIFS('Adyen'!$E$11:$E$207,'Adyen'!$A$11:$A$207,"<="&$AO11,'Adyen'!$G$11:$G$207,">"&$AO11) | P11: =SUMIFS('Nuvei'!$B$11:$B$296,'Nuvei'!$A$11:$A$296,">="&$AN11,'Nuvei'!$A$11:$A$296,"<="&$AO11) | Q11: =SUMIFS('Nuvei'!$C$11:$C$296,'Nuvei'!$A$11:$A$296,">="&$AN11,'Nuvei'!$A$11:$A$296,"<="&$AO11) | R11: =P11-Q11 | S11: =SUMIFS('Nuvei'!$E$11:$E$296,'Nuvei'!$G$11:$G$296,">="&$AN11,'Nuvei'!$G$11:$G$296,"<="&$AO11) | T11: =SUMIFS('Nuvei'!$E$11:$E$296,'Nuvei'!$A$11:$A$296,"<="&$AO11,'Nuvei'!$G$11:$G$296,">"&$AO11) | U11: =SUMIFS('Shift4'!$B$11:$B$116,'Shift4'!$A$11:$A$116,">="&$AN11,'Shift4'!$A$11:$A$116,"<="&$AO11) | V11: =SUMIFS('Shift4'!$C$11:$C$116,'Shift4'!$A$11:$A$116,">="&$AN11,'Shift4'!$A$11:$A$116,"<="&$AO11) | W11: =U11-V11 | X11: =SUMIFS('Shift4'!$E$11:$E$116,'Shift4'!$G$11:$G$116,">="&$AN11,'Shift4'!$G$11:$G$116,"<="&$AO11) | Y11: =SUMIFS('Shift4'!$E$11:$E$116,'Shift4'!$A$11:$A$116,"<="&$AO11,'Shift4'!$G$11:$G$116,">"&$AO11) | Z11: =SUMIFS('Paysafe'!$B$11:$B$44,'Paysafe'!$A$11:$A$44,">="&$AN11,'Paysafe'!$A$11:$A$44,"<="&$AO11) | AA11: =SUMIFS('Paysafe'!$C$11:$C$44,'Paysafe'!$A$11:$A$44,">="&$AN11,'Paysafe'!$A$11:$A$44,"<="&$AO11) | AB11: =Z11-AA11 | AC11: =SUMIFS('Paysafe'!$E$11:$E$44,'Paysafe'!$G$11:$G$44,">="&$AN11,'Paysafe'!$G$11:$G$44,"<="&$AO11) | AD11: =SUMIFS('Paysafe'!$E$11:$E$44,'Paysafe'!$A$11:$A$44,"<="&$AO11,'Paysafe'!$G$11:$G$44,">"&$AO11) | AE11: =K11+P11+U11+Z11 | AF11: =L11+Q11+V11+AA11 | AG11: =M11+R11+W11+AB11 | AH11: =N11+S11+X11+AC11 | AI11: =O11+T11+Y11+AD11 | AN11: 45950 | AO11: 45956
A12: 45932 | B12: =SUMIFS('Adyen'!$E$11:$E$207,'Adyen'!$G$11:$G$207,$A12) | C12: =SUMIFS('Nuvei'!$E$11:$E$296,'Nuvei'!$G$11:$G$296,$A12) | D12: =SUMIFS('Shift4'!$E$11:$E$116,'Shift4'!$G$11:$G$116,$A12) | E12: =SUMIFS('Paysafe'!$E$11:$E$44,'Paysafe'!$G$11:$G$44,$A12) | F12: =SUM(B12:E12) | H12: 2025 | I12: W44 | J12: 27/10 - 02/11/2025 | K12: =SUMIFS('Adyen'!$B$11:$B$207,'Adyen'!$A$11:$A$207,">="&$AN12,'Adyen'!$A$11:$A$207,"<="&$AO12) | L12: =SUMIFS('Adyen'!$C$11:$C$207,'Adyen'!$A$11:$A$207,">="&$AN12,'Adyen'!$A$11:$A$207,"<="&$AO12) | M12: =K12-L12 | N12: =SUMIFS('Adyen'!$E$11:$E$207,'Adyen'!$G$11:$G$207,">="&$AN12,'Adyen'!$G$11:$G$207,"<="&$AO12) | O12: =SUMIFS('Adyen'!$E$11:$E$207,'Adyen'!$A$11:$A$207,"<="&$AO12,'Adyen'!$G$11:$G$207,">"&$AO12) | P12: =SUMIFS('Nuvei'!$B$11:$B$296,'Nuvei'!$A$11:$A$296,">="&$AN12,'Nuvei'!$A$11:$A$296,"<="&$AO12) | Q12: =SUMIFS('Nuvei'!$C$11:$C$296,'Nuvei'!$A$11:$A$296,">="&$AN12,'Nuvei'!$A$11:$A$296,"<="&$AO12) | R12: =P12-Q12 | S12: =SUMIFS('Nuvei'!$E$11:$E$296,'Nuvei'!$G$11:$G$296,">="&$AN12,'Nuvei'!$G$11:$G$296,"<="&$AO12) | T12: =SUMIFS('Nuvei'!$E$11:$E$296,'Nuvei'!$A$11:$A$296,"<="&$AO12,'Nuvei'!$G$11:$G$296,">"&$AO12) | U12: =SUMIFS('Shift4'!$B$11:$B$116,'Shift4'!$A$11:$A$116,">="&$AN12,'Shift4'!$A$11:$A$116,"<="&$AO12) | V12: =SUMIFS('Shift4'!$C$11:$C$116,'Shift4'!$A$11:$A$116,">="&$AN12,'Shift4'!$A$11:$A$116,"<="&$AO12) | W12: =U12-V12 | X12: =SUMIFS('Shift4'!$E$11:$E$116,'Shift4'!$G$11:$G$116,">="&$AN12,'Shift4'!$G$11:$G$116,"<="&$AO12) | Y12: =SUMIFS('Shift4'!$E$11:$E$116,'Shift4'!$A$11:$A$116,"<="&$AO12,'Shift4'!$G$11:$G$116,">"&$AO12) | Z12: =SUMIFS('Paysafe'!$B$11:$B$44,'Paysafe'!$A$11:$A$44,">="&$AN12,'Paysafe'!$A$11:$A$44,"<="&$AO12) | AA12: =SUMIFS('Paysafe'!$C$11:$C$44,'Paysafe'!$A$11:$A$44,">="&$AN12,'Paysafe'!$A$11:$A$44,"<="&$AO12) | AB12: =Z12-AA12 | AC12: =SUMIFS('Paysafe'!$E$11:$E$44,'Paysafe'!$G$11:$G$44,">="&$AN12,'Paysafe'!$G$11:$G$44,"<="&$AO12) | AD12: =SUMIFS('Paysafe'!$E$11:$E$44,'Paysafe'!$A$11:$A$44,"<="&$AO12,'Paysafe'!$G$11:$G$44,">"&$AO12) | AE12: =K12+P12+U12+Z12 | AF12: =L12+Q12+V12+AA12 | AG12: =M12+R12+W12+AB12 | AH12: =N12+S12+X12+AC12 | AI12: =O12+T12+Y12+AD12 | AN12: 45957 | AO12: 45963
A13: 45933 | B13: =SUMIFS('Adyen'!$E$11:$E$207,'Adyen'!$G$11:$G$207,$A13) | C13: =SUMIFS('Nuvei'!$E$11:$E$296,'Nuvei'!$G$11:$G$296,$A13) | D13: =SUMIFS('Shift4'!$E$11:$E$116,'Shift4'!$G$11:$G$116,$A13) | E13: =SUMIFS('Paysafe'!$E$11:$E$44,'Paysafe'!$G$11:$G$44,$A13) | F13: =SUM(B13:E13) | H13: 2025 | I13: W45 | J13: 03/11 - 09/11/2025 | K13: =SUMIFS('Adyen'!$B$11:$B$207,'Adyen'!$A$11:$A$207,">="&$AN13,'Adyen'!$A$11:$A$207,"<="&$AO13) | L13: =SUMIFS('Adyen'!$C$11:$C$207,'Adyen'!$A$11:$A$207,">="&$AN13,'Adyen'!$A$11:$A$207,"<="&$AO13) | M13: =K13-L13 | N13: =SUMIFS('Adyen'!$E$11:$E$207,'Adyen'!$G$11:$G$207,">="&$AN13,'Adyen'!$G$11:$G$207,"<="&$AO13) | O13: =SUMIFS('Adyen'!$E$11:$E$207,'Adyen'!$A$11:$A$207,"<="&$AO13,'Adyen'!$G$11:$G$207,">"&$AO13) | P13: =SUMIFS('Nuvei'!$B$11:$B$296,'Nuvei'!$A$11:$A$296,">="&$AN13,'Nuvei'!$A$11:$A$296,"<="&$AO13) | Q13: =SUMIFS('Nuvei'!$C$11:$C$296,'Nuvei'!$A$11:$A$296,">="&$AN13,'Nuvei'!$A$11:$A$296,"<="&$AO13) | R13: =P13-Q13 | S13: =SUMIFS('Nuvei'!$E$11:$E$296,'Nuvei'!$G$11:$G$296,">="&$AN13,'Nuvei'!$G$11:$G$296,"<="&$AO13) | T13: =SUMIFS('Nuvei'!$E$11:$E$296,'Nuvei'!$A$11:$A$296,"<="&$AO13,'Nuvei'!$G$11:$G$296,">"&$AO13) | U13: =SUMIFS('Shift4'!$B$11:$B$116,'Shift4'!$A$11:$A$116,">="&$AN13,'Shift4'!$A$11:$A$116,"<="&$AO13) | V13: =SUMIFS('Shift4'!$C$11:$C$116,'Shift4'!$A$11:$A$116,">="&$AN13,'Shift4'!$A$11:$A$116,"<="&$AO13) | W13: =U13-V13 | X13: =SUMIFS('Shift4'!$E$11:$E$116,'Shift4'!$G$11:$G$116,">="&$AN13,'Shift4'!$G$11:$G$116,"<="&$AO13) | Y13: =SUMIFS('Shift4'!$E$11:$E$116,'Shift4'!$A$11:$A$116,"<="&$AO13,'Shift4'!$G$11:$G$116,">"&$AO13) | Z13: =SUMIFS('Paysafe'!$B$11:$B$44,'Paysafe'!$A$11:$A$44,">="&$AN13,'Paysafe'!$A$11:$A$44,"<="&$AO13) | AA13: =SUMIFS('Paysafe'!$C$11:$C$44,'Paysafe'!$A$11:$A$44,">="&$AN13,'Paysafe'!$A$11:$A$44,"<="&$AO13) | AB13: =Z13-AA13 | AC13: =SUMIFS('Paysafe'!$E$11:$E$44,'Paysafe'!$G$11:$G$44,">="&$AN13,'Paysafe'!$G$11:$G$44,"<="&$AO13) | AD13: =SUMIFS('Paysafe'!$E$11:$E$44,'Paysafe'!$A$11:$A$44,"<="&$AO13,'Paysafe'!$G$11:$G$44,">"&$AO13) | AE13: =K13+P13+U13+Z13 | AF13: =L13+Q13+V13+AA13 | AG13: =M13+R13+W13+AB13 | AH13: =N13+S13+X13+AC13 | AI13: =O13+T13+Y13+AD13 | AN13: 45964 | AO13: 45970
A14: 45934 | B14: =SUMIFS('Adyen'!$E$11:$E$207,'Adyen'!$G$11:$G$207,$A14) | C14: =SUMIFS('Nuvei'!$E$11:$E$296,'Nuvei'!$G$11:$G$296,$A14) | D14: =SUMIFS('Shift4'!$E$11:$E$116,'Shift4'!$G$11:$G$116,$A14) | E14: =SUMIFS('Paysafe'!$E$11:$E$44,'Paysafe'!$G$11:$G$44,$A14) | F14: =SUM(B14:E14) | H14: 2025 | I14: W46 | J14: 10/11 - 16/11/2025 | K14: =SUMIFS('Adyen'!$B$11:$B$207,'Adyen'!$A$11:$A$207,">="&$AN14,'Adyen'!$A$11:$A$207,"<="&$AO14) | L14: =SUMIFS('Adyen'!$C$11:$C$207,'Adyen'!$A$11:$A$207,">="&$AN14,'Adyen'!$A$11:$A$207,"<="&$AO14) | M14: =K14-L14 | N14: =SUMIFS('Adyen'!$E$11:$E$207,'Adyen'!$G$11:$G$207,">="&$AN14,'Adyen'!$G$11:$G$207,"<="&$AO14) | O14: =SUMIFS('Adyen'!$E$11:$E$207,'Adyen'!$A$11:$A$207,"<="&$AO14,'Adyen'!$G$11:$G$207,">"&$AO14) | P14: =SUMIFS('Nuvei'!$B$11:$B$296,'Nuvei'!$A$11:$A$296,">="&$AN14,'Nuvei'!$A$11:$A$296,"<="&$AO14) | Q14: =SUMIFS('Nuvei'!$C$11:$C$296,'Nuvei'!$A$11:$A$296,">="&$AN14,'Nuvei'!$A$11:$A$296,"<="&$AO14) | R14: =P14-Q14 | S14: =SUMIFS('Nuvei'!$E$11:$E$296,'Nuvei'!$G$11:$G$296,">="&$AN14,'Nuvei'!$G$11:$G$296,"<="&$AO14) | T14: =SUMIFS('Nuvei'!$E$11:$E$296,'Nuvei'!$A$11:$A$296,"<="&$AO14,'Nuvei'!$G$11:$G$296,">"&$AO14) | U14: =SUMIFS('Shift4'!$B$11:$B$116,'Shift4'!$A$11:$A$116,">="&$AN14,'Shift4'!$A$11:$A$116,"<="&$AO14) | V14: =SUMIFS('Shift4'!$C$11:$C$116,'Shift4'!$A$11:$A$116,">="&$AN14,'Shift4'!$A$11:$A$116,"<="&$AO14) | W14: =U14-V14 | X14: =SUMIFS('Shift4'!$E$11:$E$116,'Shift4'!$G$11:$G$116,">="&$AN14,'Shift4'!$G$11:$G$116,"<="&$AO14) | Y14: =SUMIFS('Shift4'!$E$11:$E$116,'Shift4'!$A$11:$A$116,"<="&$AO14,'Shift4'!$G$11:$G$116,">"&$AO14) | Z14: =SUMIFS('Paysafe'!$B$11:$B$44,'Paysafe'!$A$11:$A$44,">="&$AN14,'Paysafe'!$A$11:$A$44,"<="&$AO14) | AA14: =SUMIFS('Paysafe'!$C$11:$C$44,'Paysafe'!$A$11:$A$44,">="&$AN14,'Paysafe'!$A$11:$A$44,"<="&$AO14) | AB14: =Z14-AA14 | AC14: =SUMIFS('Paysafe'!$E$11:$E$44,'Paysafe'!$G$11:$G$44,">="&$AN14,'Paysafe'!$G$11:$G$44,"<="&$AO14) | AD14: =SUMIFS('Paysafe'!$E$11:$E$44,'Paysafe'!$A$11:$A$44,"<="&$AO14,'Paysafe'!$G$11:$G$44,">"&$AO14) | AE14: =K14+P14+U14+Z14 | AF14: =L14+Q14+V14+AA14 | AG14: =M14+R14+W14+AB14 | AH14: =N14+S14+X14+AC14 | AI14: =O14+T14+Y14+AD14 | AN14: 45971 | AO14: 45977
A15: 45935 | B15: =SUMIFS('Adyen'!$E$11:$E$207,'Adyen'!$G$11:$G$207,$A15) | C15: =SUMIFS('Nuvei'!$E$11:$E$296,'Nuvei'!$G$11:$G$296,$A15) | D15: =SUMIFS('Shift4'!$E$11:$E$116,'Shift4'!$G$11:$G$116,$A15) | E15: =SUMIFS('Paysafe'!$E$11:$E$44,'Paysafe'!$G$11:$G$44,$A15) | F15: =SUM(B15:E15) | H15: 2025 | I15: W47 | J15: 17/11 - 23/11/2025 | K15: =SUMIFS('Adyen'!$B$11:$B$207,'Adyen'!$A$11:$A$207,">="&$AN15,'Adyen'!$A$11:$A$207,"<="&$AO15) | L15: =SUMIFS('Adyen'!$C$11:$C$207,'Adyen'!$A$11:$A$207,">="&$AN15,'Adyen'!$A$11:$A$207,"<="&$AO15) | M15: =K15-L15 | N15: =SUMIFS('Adyen'!$E$11:$E$207,'Adyen'!$G$11:$G$207,">="&$AN15,'Adyen'!$G$11:$G$207,"<="&$AO15) | O15: =SUMIFS('Adyen'!$E$11:$E$207,'Adyen'!$A$11:$A$207,"<="&$AO15,'Adyen'!$G$11:$G$207,">"&$AO15) | P15: =SUMIFS('Nuvei'!$B$11:$B$296,'Nuvei'!$A$11:$A$296,">="&$AN15,'Nuvei'!$A$11:$A$296,"<="&$AO15) | Q15: =SUMIFS('Nuvei'!$C$11:$C$296,'Nuvei'!$A$11:$A$296,">="&$AN15,'Nuvei'!$A$11:$A$296,"<="&$AO15) | R15: =P15-Q15 | S15: =SUMIFS('Nuvei'!$E$11:$E$296,'Nuvei'!$G$11:$G$296,">="&$AN15,'Nuvei'!$G$11:$G$296,"<="&$AO15) | T15: =SUMIFS('Nuvei'!$E$11:$E$296,'Nuvei'!$A$11:$A$296,"<="&$AO15,'Nuvei'!$G$11:$G$296,">"&$AO15) | U15: =SUMIFS('Shift4'!$B$11:$B$116,'Shift4'!$A$11:$A$116,">="&$AN15,'Shift4'!$A$11:$A$116,"<="&$AO15) | V15: =SUMIFS('Shift4'!$C$11:$C$116,'Shift4'!$A$11:$A$116,">="&$AN15,'Shift4'!$A$11:$A$116,"<="&$AO15) | W15: =U15-V15 | X15: =SUMIFS('Shift4'!$E$11:$E$116,'Shift4'!$G$11:$G$116,">="&$AN15,'Shift4'!$G$11:$G$116,"<="&$AO15) | Y15: =SUMIFS('Shift4'!$E$11:$E$116,'Shift4'!$A$11:$A$116,"<="&$AO15,'Shift4'!$G$11:$G$116,">"&$AO15) | Z15: =SUMIFS('Paysafe'!$B$11:$B$44,'Paysafe'!$A$11:$A$44,">="&$AN15,'Paysafe'!$A$11:$A$44,"<="&$AO15) | AA15: =SUMIFS('Paysafe'!$C$11:$C$44,'Paysafe'!$A$11:$A$44,">="&$AN15,'Paysafe'!$A$11:$A$44,"<="&$AO15) | AB15: =Z15-AA15 | AC15: =SUMIFS('Paysafe'!$E$11:$E$44,'Paysafe'!$G$11:$G$44,">="&$AN15,'Paysafe'!$G$11:$G$44,"<="&$AO15) | AD15: =SUMIFS('Paysafe'!$E$11:$E$44,'Paysafe'!$A$11:$A$44,"<="&$AO15,'Paysafe'!$G$11:$G$44,">"&$AO15) | AE15: =K15+P15+U15+Z15 | AF15: =L15+Q15+V15+AA15 | AG15: =M15+R15+W15+AB15 | AH15: =N15+S15+X15+AC15 | AI15: =O15+T15+Y15+AD15 | AN15: 45978 | AO15: 45984
A16: 45936 | B16: =SUMIFS('Adyen'!$E$11:$E$207,'Adyen'!$G$11:$G$207,$A16) | C16: =SUMIFS('Nuvei'!$E$11:$E$296,'Nuvei'!$G$11:$G$296,$A16) | D16: =SUMIFS('Shift4'!$E$11:$E$116,'Shift4'!$G$11:$G$116,$A16) | E16: =SUMIFS('Paysafe'!$E$11:$E$44,'Paysafe'!$G$11:$G$44,$A16) | F16: =SUM(B16:E16) | H16: 2025 | I16: W48 | J16: 24/11 - 30/11/2025 | K16: =SUMIFS('Adyen'!$B$11:$B$207,'Adyen'!$A$11:$A$207,">="&$AN16,'Adyen'!$A$11:$A$207,"<="&$AO16) | L16: =SUMIFS('Adyen'!$C$11:$C$207,'Adyen'!$A$11:$A$207,">="&$AN16,'Adyen'!$A$11:$A$207,"<="&$AO16) | M16: =K16-L16 | N16: =SUMIFS('Adyen'!$E$11:$E$207,'Adyen'!$G$11:$G$207,">="&$AN16,'Adyen'!$G$11:$G$207,"<="&$AO16) | O16: =SUMIFS('Adyen'!$E$11:$E$207,'Adyen'!$A$11:$A$207,"<="&$AO16,'Adyen'!$G$11:$G$207,">"&$AO16) | P16: =SUMIFS('Nuvei'!$B$11:$B$296,'Nuvei'!$A$11:$A$296,">="&$AN16,'Nuvei'!$A$11:$A$296,"<="&$AO16) | Q16: =SUMIFS('Nuvei'!$C$11:$C$296,'Nuvei'!$A$11:$A$296,">="&$AN16,'Nuvei'!$A$11:$A$296,"<="&$AO16) | R16: =P16-Q16 | S16: =SUMIFS('Nuvei'!$E$11:$E$296,'Nuvei'!$G$11:$G$296,">="&$AN16,'Nuvei'!$G$11:$G$296,"<="&$AO16) | T16: =SUMIFS('Nuvei'!$E$11:$E$296,'Nuvei'!$A$11:$A$296,"<="&$AO16,'Nuvei'!$G$11:$G$296,">"&$AO16) | U16: =SUMIFS('Shift4'!$B$11:$B$116,'Shift4'!$A$11:$A$116,">="&$AN16,'Shift4'!$A$11:$A$116,"<="&$AO16) | V16: =SUMIFS('Shift4'!$C$11:$C$116,'Shift4'!$A$11:$A$116,">="&$AN16,'Shift4'!$A$11:$A$116,"<="&$AO16) | W16: =U16-V16 | X16: =SUMIFS('Shift4'!$E$11:$E$116,'Shift4'!$G$11:$G$116,">="&$AN16,'Shift4'!$G$11:$G$116,"<="&$AO16) | Y16: =SUMIFS('Shift4'!$E$11:$E$116,'Shift4'!$A$11:$A$116,"<="&$AO16,'Shift4'!$G$11:$G$116,">"&$AO16) | Z16: =SUMIFS('Paysafe'!$B$11:$B$44,'Paysafe'!$A$11:$A$44,">="&$AN16,'Paysafe'!$A$11:$A$44,"<="&$AO16) | AA16: =SUMIFS('Paysafe'!$C$11:$C$44,'Paysafe'!$A$11:$A$44,">="&$AN16,'Paysafe'!$A$11:$A$44,"<="&$AO16) | AB16: =Z16-AA16 | AC16: =SUMIFS('Paysafe'!$E$11:$E$44,'Paysafe'!$G$11:$G$44,">="&$AN16,'Paysafe'!$G$11:$G$44,"<="&$AO16) | AD16: =SUMIFS('Paysafe'!$E$11:$E$44,'Paysafe'!$A$11:$A$44,"<="&$AO16,'Paysafe'!$G$11:$G$44,">"&$AO16) | AE16: =K16+P16+U16+Z16 | AF16: =L16+Q16+V16+AA16 | AG16: =M16+R16+W16+AB16 | AH16: =N16+S16+X16+AC16 | AI16: =O16+T16+Y16+AD16 | AN16: 45985 | AO16: 45991
A17: 45937 | B17: =SUMIFS('Adyen'!$E$11:$E$207,'Adyen'!$G$11:$G$207,$A17) | C17: =SUMIFS('Nuvei'!$E$11:$E$296,'Nuvei'!$G$11:$G$296,$A17) | D17: =SUMIFS('Shift4'!$E$11:$E$116,'Shift4'!$G$11:$G$116,$A17) | E17: =SUMIFS('Paysafe'!$E$11:$E$44,'Paysafe'!$G$11:$G$44,$A17) | F17: =SUM(B17:E17) | H17: 2025 | I17: W49 | J17: 01/12 - 07/12/2025 | K17: =SUMIFS('Adyen'!$B$11:$B$207,'Adyen'!$A$11:$A$207,">="&$AN17,'Adyen'!$A$11:$A$207,"<="&$AO17) | L17: =SUMIFS('Adyen'!$C$11:$C$207,'Adyen'!$A$11:$A$207,">="&$AN17,'Adyen'!$A$11:$A$207,"<="&$AO17) | M17: =K17-L17 | N17: =SUMIFS('Adyen'!$E$11:$E$207,'Adyen'!$G$11:$G$207,">="&$AN17,'Adyen'!$G$11:$G$207,"<="&$AO17) | O17: =SUMIFS('Adyen'!$E$11:$E$207,'Adyen'!$A$11:$A$207,"<="&$AO17,'Adyen'!$G$11:$G$207,">"&$AO17) | P17: =SUMIFS('Nuvei'!$B$11:$B$296,'Nuvei'!$A$11:$A$296,">="&$AN17,'Nuvei'!$A$11:$A$296,"<="&$AO17) | Q17: =SUMIFS('Nuvei'!$C$11:$C$296,'Nuvei'!$A$11:$A$296,">="&$AN17,'Nuvei'!$A$11:$A$296,"<="&$AO17) | R17: =P17-Q17 | S17: =SUMIFS('Nuvei'!$E$11:$E$296,'Nuvei'!$G$11:$G$296,">="&$AN17,'Nuvei'!$G$11:$G$296,"<="&$AO17) | T17: =SUMIFS('Nuvei'!$E$11:$E$296,'Nuvei'!$A$11:$A$296,"<="&$AO17,'Nuvei'!$G$11:$G$296,">"&$AO17) | U17: =SUMIFS('Shift4'!$B$11:$B$116,'Shift4'!$A$11:$A$116,">="&$AN17,'Shift4'!$A$11:$A$116,"<="&$AO17) | V17: =SUMIFS('Shift4'!$C$11:$C$116,'Shift4'!$A$11:$A$116,">="&$AN17,'Shift4'!$A$11:$A$116,"<="&$AO17) | W17: =U17-V17 | X17: =SUMIFS('Shift4'!$E$11:$E$116,'Shift4'!$G$11:$G$116,">="&$AN17,'Shift4'!$G$11:$G$116,"<="&$AO17) | Y17: =SUMIFS('Shift4'!$E$11:$E$116,'Shift4'!$A$11:$A$116,"<="&$AO17,'Shift4'!$G$11:$G$116,">"&$AO17) | Z17: =SUMIFS('Paysafe'!$B$11:$B$44,'Paysafe'!$A$11:$A$44,">="&$AN17,'Paysafe'!$A$11:$A$44,"<="&$AO17) | AA17: =SUMIFS('Paysafe'!$C$11:$C$44,'Paysafe'!$A$11:$A$44,">="&$AN17,'Paysafe'!$A$11:$A$44,"<="&$AO17) | AB17: =Z17-AA17 | AC17: =SUMIFS('Paysafe'!$E$11:$E$44,'Paysafe'!$G$11:$G$44,">="&$AN17,'Paysafe'!$G$11:$G$44,"<="&$AO17) | AD17: =SUMIFS('Paysafe'!$E$11:$E$44,'Paysafe'!$A$11:$A$44,"<="&$AO17,'Paysafe'!$G$11:$G$44,">"&$AO17) | AE17: =K17+P17+U17+Z17 | AF17: =L17+Q17+V17+AA17 | AG17: =M17+R17+W17+AB17 | AH17: =N17+S17+X17+AC17 | AI17: =O17+T17+Y17+AD17 | AN17: 45992 | AO17: 45998
A18: 45938 | B18: =SUMIFS('Adyen'!$E$11:$E$207,'Adyen'!$G$11:$G$207,$A18) | C18: =SUMIFS('Nuvei'!$E$11:$E$296,'Nuvei'!$G$11:$G$296,$A18) | D18: =SUMIFS('Shift4'!$E$11:$E$116,'Shift4'!$G$11:$G$116,$A18) | E18: =SUMIFS('Paysafe'!$E$11:$E$44,'Paysafe'!$G$11:$G$44,$A18) | F18: =SUM(B18:E18) | H18: 2025 | I18: W50 | J18: 08/12 - 14/12/2025 | K18: =SUMIFS('Adyen'!$B$11:$B$207,'Adyen'!$A$11:$A$207,">="&$AN18,'Adyen'!$A$11:$A$207,"<="&$AO18) | L18: =SUMIFS('Adyen'!$C$11:$C$207,'Adyen'!$A$11:$A$207,">="&$AN18,'Adyen'!$A$11:$A$207,"<="&$AO18) | M18: =K18-L18 | N18: =SUMIFS('Adyen'!$E$11:$E$207,'Adyen'!$G$11:$G$207,">="&$AN18,'Adyen'!$G$11:$G$207,"<="&$AO18) | O18: =SUMIFS('Adyen'!$E$11:$E$207,'Adyen'!$A$11:$A$207,"<="&$AO18,'Adyen'!$G$11:$G$207,">"&$AO18) | P18: =SUMIFS('Nuvei'!$B$11:$B$296,'Nuvei'!$A$11:$A$296,">="&$AN18,'Nuvei'!$A$11:$A$296,"<="&$AO18) | Q18: =SUMIFS('Nuvei'!$C$11:$C$296,'Nuvei'!$A$11:$A$296,">="&$AN18,'Nuvei'!$A$11:$A$296,"<="&$AO18) | R18: =P18-Q18 | S18: =SUMIFS('Nuvei'!$E$11:$E$296,'Nuvei'!$G$11:$G$296,">="&$AN18,'Nuvei'!$G$11:$G$296,"<="&$AO18) | T18: =SUMIFS('Nuvei'!$E$11:$E$296,'Nuvei'!$A$11:$A$296,"<="&$AO18,'Nuvei'!$G$11:$G$296,">"&$AO18) | U18: =SUMIFS('Shift4'!$B$11:$B$116,'Shift4'!$A$11:$A$116,">="&$AN18,'Shift4'!$A$11:$A$116,"<="&$AO18) | V18: =SUMIFS('Shift4'!$C$11:$C$116,'Shift4'!$A$11:$A$116,">="&$AN18,'Shift4'!$A$11:$A$116,"<="&$AO18) | W18: =U18-V18 | X18: =SUMIFS('Shift4'!$E$11:$E$116,'Shift4'!$G$11:$G$116,">="&$AN18,'Shift4'!$G$11:$G$116,"<="&$AO18) | Y18: =SUMIFS('Shift4'!$E$11:$E$116,'Shift4'!$A$11:$A$116,"<="&$AO18,'Shift4'!$G$11:$G$116,">"&$AO18) | Z18: =SUMIFS('Paysafe'!$B$11:$B$44,'Paysafe'!$A$11:$A$44,">="&$AN18,'Paysafe'!$A$11:$A$44,"<="&$AO18) | AA18: =SUMIFS('Paysafe'!$C$11:$C$44,'Paysafe'!$A$11:$A$44,">="&$AN18,'Paysafe'!$A$11:$A$44,"<="&$AO18) | AB18: =Z18-AA18 | AC18: =SUMIFS('Paysafe'!$E$11:$E$44,'Paysafe'!$G$11:$G$44,">="&$AN18,'Paysafe'!$G$11:$G$44,"<="&$AO18) | AD18: =SUMIFS('Paysafe'!$E$11:$E$44,'Paysafe'!$A$11:$A$44,"<="&$AO18,'Paysafe'!$G$11:$G$44,">"&$AO18) | AE18: =K18+P18+U18+Z18 | AF18: =L18+Q18+V18+AA18 | AG18: =M18+R18+W18+AB18 | AH18: =N18+S18+X18+AC18 | AI18: =O18+T18+Y18+AD18 | AN18: 45999 | AO18: 46005
... A52: 45972 | B52: =SUMIFS('Adyen'!$E$11:$E$207,'Adyen'!$G$11:$G$207,$A52) | C52: =SUMIFS('Nuvei'!$E$11:$E$296,'Nuvei'!$G$11:$G$296,$A52) | D52: =SUMIFS('Shift4'!$E$11:$E$116,'Shift4'!$G$11:$G$116,$A52) | E52: =SUMIFS('Paysafe'!$E$11:$E$44,'Paysafe'!$G$11:$G$44,$A52) | F52: =SUM(B52:E52) | H52: 2026 | I52: W32 | J52: 03/08 - 09/08/2026 | K52: =SUMIFS('Adyen'!$B$11:$B$207,'Adyen'!$A$11:$A$207,">="&$AN52,'Adyen'!$A$11:$A$207,"<="&$AO52) | L52: =SUMIFS('Adyen'!$C$11:$C$207,'Adyen'!$A$11:$A$207,">="&$AN52,'Adyen'!$A$11:$A$207,"<="&$AO52) | M52: =K52-L52 | N52: =SUMIFS('Adyen'!$E$11:$E$207,'Adyen'!$G$11:$G$207,">="&$AN52,'Adyen'!$G$11:$G$207,"<="&$AO52) | O52: =SUMIFS('Adyen'!$E$11:$E$207,'Adyen'!$A$11:$A$207,"<="&$AO52,'Adyen'!$G$11:$G$207,">"&$AO52) | P52: =SUMIFS('Nuvei'!$B$11:$B$296,'Nuvei'!$A$11:$A$296,">="&$AN52,'Nuvei'!$A$11:$A$296,"<="&$AO52) | Q52: =SUMIFS('Nuvei'!$C$11:$C$296,'Nuvei'!$A$11:$A$296,">="&$AN52,'Nuvei'!$A$11:$A$296,"<="&$AO52) | R52: =P52-Q52 | S52: =SUMIFS('Nuvei'!$E$11:$E$296,'Nuvei'!$G$11:$G$296,">="&$AN52,'Nuvei'!$G$11:$G$296,"<="&$AO52) | T52: =SUMIFS('Nuvei'!$E$11:$E$296,'Nuvei'!$A$11:$A$296,"<="&$AO52,'Nuvei'!$G$11:$G$296,">"&$AO52) | U52: =SUMIFS('Shift4'!$B$11:$B$116,'Shift4'!$A$11:$A$116,">="&$AN52,'Shift4'!$A$11:$A$116,"<="&$AO52) | V52: =SUMIFS('Shift4'!$C$11:$C$116,'Shift4'!$A$11:$A$116,">="&$AN52,'Shift4'!$A$11:$A$116,"<="&$AO52) | W52: =U52-V52 | X52: =SUMIFS('Shift4'!$E$11:$E$116,'Shift4'!$G$11:$G$116,">="&$AN52,'Shift4'!$G$11:$G$116,"<="&$AO52) | Y52: =SUMIFS('Shift4'!$E$11:$E$116,'Shift4'!$A$11:$A$116,"<="&$AO52,'Shift4'!$G$11:$G$116,">"&$AO52) | Z52: =SUMIFS('Paysafe'!$B$11:$B$44,'Paysafe'!$A$11:$A$44,">="&$AN52,'Paysafe'!$A$11:$A$44,"<="&$AO52) | AA52: =SUMIFS('Paysafe'!$C$11:$C$44,'Paysafe'!$A$11:$A$44,">="&$AN52,'Paysafe'!$A$11:$A$44,"<="&$AO52) | AB52: =Z52-AA52 | AC52: =SUMIFS('Paysafe'!$E$11:$E$44,'Paysafe'!$G$11:$G$44,">="&$AN52,'Paysafe'!$G$11:$G$44,"<="&$AO52) | AD52: =SUMIFS('Paysafe'!$E$11:$E$44,'Paysafe'!$A$11:$A$44,"<="&$AO52,'Paysafe'!$G$11:$G$44,">"&$AO52) | AE52: =K52+P52+U52+Z52 | AF52: =L52+Q52+V52+AA52 | AG52: =M52+R52+W52+AB52 | AH52: =N52+S52+X52+AC52 | AI52: =O52+T52+Y52+AD52 | AN52: 46237 | AO52: 46243
A53: 45973 | B53: =SUMIFS('Adyen'!$E$11:$E$207,'Adyen'!$G$11:$G$207,$A53) | C53: =SUMIFS('Nuvei'!$E$11:$E$296,'Nuvei'!$G$11:$G$296,$A53) | D53: =SUMIFS('Shift4'!$E$11:$E$116,'Shift4'!$G$11:$G$116,$A53) | E53: =SUMIFS('Paysafe'!$E$11:$E$44,'Paysafe'!$G$11:$G$44,$A53) | F53: =SUM(B53:E53)
A54: 45974 | B54: =SUMIFS('Adyen'!$E$11:$E$207,'Adyen'!$G$11:$G$207,$A54) | C54: =SUMIFS('Nuvei'!$E$11:$E$296,'Nuvei'!$G$11:$G$296,$A54) | D54: =SUMIFS('Shift4'!$E$11:$E$116,'Shift4'!$G$11:$G$116,$A54) | E54: =SUMIFS('Paysafe'!$E$11:$E$44,'Paysafe'!$G$11:$G$44,$A54) | F54: =SUM(B54:E54) | H54: → Ventas = bruto vendido · Fees = comisiones · Venta Neta = Ventas−Fees · Collected = neto liquidado esa semana · Retenido = neto vendido hasta el domingo sin liquidar. (importes en €)
A55: 45975 | B55: =SUMIFS('Adyen'!$E$11:$E$207,'Adyen'!$G$11:$G$207,$A55) | C55: =SUMIFS('Nuvei'!$E$11:$E$296,'Nuvei'!$G$11:$G$296,$A55) | D55: =SUMIFS('Shift4'!$E$11:$E$116,'Shift4'!$G$11:$G$116,$A55) | E55: =SUMIFS('Paysafe'!$E$11:$E$44,'Paysafe'!$G$11:$G$44,$A55) | F55: =SUM(B55:E55)
A56: 45976 | B56: =SUMIFS('Adyen'!$E$11:$E$207,'Adyen'!$G$11:$G$207,$A56) | C56: =SUMIFS('Nuvei'!$E$11:$E$296,'Nuvei'!$G$11:$G$296,$A56) | D56: =SUMIFS('Shift4'!$E$11:$E$116,'Shift4'!$G$11:$G$116,$A56) | E56: =SUMIFS('Paysafe'!$E$11:$E$44,'Paysafe'!$G$11:$G$44,$A56) | F56: =SUM(B56:E56)
A57: 45977 | B57: =SUMIFS('Adyen'!$E$11:$E$207,'Adyen'!$G$11:$G$207,$A57) | C57: =SUMIFS('Nuvei'!$E$11:$E$296,'Nuvei'!$G$11:$G$296,$A57) | D57: =SUMIFS('Shift4'!$E$11:$E$116,'Shift4'!$G$11:$G$116,$A57) | E57: =SUMIFS('Paysafe'!$E$11:$E$44,'Paysafe'!$G$11:$G$44,$A57) | F57: =SUM(B57:E57)
A58: 45978 | B58: =SUMIFS('Adyen'!$E$11:$E$207,'Adyen'!$G$11:$G$207,$A58) | C58: =SUMIFS('Nuvei'!$E$11:$E$296,'Nuvei'!$G$11:$G$296,$A58) | D58: =SUMIFS('Shift4'!$E$11:$E$116,'Shift4'!$G$11:$G$116,$A58) | E58: =SUMIFS('Paysafe'!$E$11:$E$44,'Paysafe'!$G$11:$G$44,$A58) | F58: =SUM(B58:E58)
A59: 45979 | B59: =SUMIFS('Adyen'!$E$11:$E$207,'Adyen'!$G$11:$G$207,$A59) | C59: =SUMIFS('Nuvei'!$E$11:$E$296,'Nuvei'!$G$11:$G$296,$A59) | D59: =SUMIFS('Shift4'!$E$11:$E$116,'Shift4'!$G$11:$G$116,$A59) | E59: =SUMIFS('Paysafe'!$E$11:$E$44,'Paysafe'!$G$11:$G$44,$A59) | F59: =SUM(B59:E59)
A60: 45980 | B60: =SUMIFS('Adyen'!$E$11:$E$207,'Adyen'!$G$11:$G$207,$A60) | C60: =SUMIFS('Nuvei'!$E$11:$E$296,'Nuvei'!$G$11:$G$296,$A60) | D60: =SUMIFS('Shift4'!$E$11:$E$116,'Shift4'!$G$11:$G$116,$A60) | E60: =SUMIFS('Paysafe'!$E$11:$E$44,'Paysafe'!$G$11:$G$44,$A60) | F60: =SUM(B60:E60)
A61: 45981 | B61: =SUMIFS('Adyen'!$E$11:$E$207,'Adyen'!$G$11:$G$207,$A61) | C61: =SUMIFS('Nuvei'!$E$11:$E$296,'Nuvei'!$G$11:$G$296,$A61) | D61: =SUMIFS('Shift4'!$E$11:$E$116,'Shift4'!$G$11:$G$116,$A61) | E61: =SUMIFS('Paysafe'!$E$11:$E$44,'Paysafe'!$G$11:$G$44,$A61) | F61: =SUM(B61:E61)
A62: 45982 | B62: =SUMIFS('Adyen'!$E$11:$E$207,'Adyen'!$G$11:$G$207,$A62) | C62: =SUMIFS('Nuvei'!$E$11:$E$296,'Nuvei'!$G$11:$G$296,$A62) | D62: =SUMIFS('Shift4'!$E$11:$E$116,'Shift4'!$G$11:$G$116,$A62) | E62: =SUMIFS('Paysafe'!$E$11:$E$44,'Paysafe'!$G$11:$G$44,$A62) | F62: =SUM(B62:E62)
A63: 45983 | B63: =SUMIFS('Adyen'!$E$11:$E$207,'Adyen'!$G$11:$G$207,$A63) | C63: =SUMIFS('Nuvei'!$E$11:$E$296,'Nuvei'!$G$11:$G$296,$A63) | D63: =SUMIFS('Shift4'!$E$11:$E$116,'Shift4'!$G$11:$G$116,$A63) | E63: =SUMIFS('Paysafe'!$E$11:$E$44,'Paysafe'!$G$11:$G$44,$A63) | F63: =SUM(B63:E63)
A64: 45984 | B64: =SUMIFS('Adyen'!$E$11:$E$207,'Adyen'!$G$11:$G$207,$A64) | C64: =SUMIFS('Nuvei'!$E$11:$E$296,'Nuvei'!$G$11:$G$296,$A64) | D64: =SUMIFS('Shift4'!$E$11:$E$116,'Shift4'!$G$11:$G$116,$A64) | E64: =SUMIFS('Paysafe'!$E$11:$E$44,'Paysafe'!$G$11:$G$44,$A64) | F64: =SUM(B64:E64)
A65: 45985 | B65: =SUMIFS('Adyen'!$E$11:$E$207,'Adyen'!$G$11:$G$207,$A65) | C65: =SUMIFS('Nuvei'!$E$11:$E$296,'Nuvei'!$G$11:$G$296,$A65) | D65: =SUMIFS('Shift4'!$E$11:$E$116,'Shift4'!$G$11:$G$116,$A65) | E65: =SUMIFS('Paysafe'!$E$11:$E$44,'Paysafe'!$G$11:$G$44,$A65) | F65: =SUM(B65:E65)
A66: 45986 | B66: =SUMIFS('Adyen'!$E$11:$E$207,'Adyen'!$G$11:$G$207,$A66) | C66: =SUMIFS('Nuvei'!$E$11:$E$296,'Nuvei'!$G$11:$G$296,$A66) | D66: =SUMIFS('Shift4'!$E$11:$E$116,'Shift4'!$G$11:$G$116,$A66) | E66: =SUMIFS('Paysafe'!$E$11:$E$44,'Paysafe'!$G$11:$G$44,$A66) | F66: =SUM(B66:E66)
... A318: 46238 | B318: =SUMIFS('Adyen'!$E$11:$E$207,'Adyen'!$G$11:$G$207,$A318) | C318: =SUMIFS('Nuvei'!$E$11:$E$296,'Nuvei'!$G$11:$G$296,$A318) | D318: =SUMIFS('Shift4'!$E$11:$E$116,'Shift4'!$G$11:$G$116,$A318) | E318: =SUMIFS('Paysafe'!$E$11:$E$44,'Paysafe'!$G$11:$G$44,$A318) | F318: =SUM(B318:E318)
A319: TOTAL | B319: =SUM(B6:B318) | C319: =SUM(C6:C318) | D319: =SUM(D6:D318) | E319: =SUM(E6:E318) | F319: =SUM(F6:F318)
A322: TOTAL RETENIDO HOY (neto, por procesador)
A323: Procesador | B323: Importe Retenido (Neto)
A324: Adyen | B324: ='Adyen'!I208
A325: Nuvei | B325: ='Nuvei'!I297
A326: Shift4 | B326: ='Shift4'!I117
A327: Paysafe | B327: ='Paysafe'!I45
...

Sheet Adyen
A1: CALCULADORA DE COBROS — ADYEN
A3: Reglas del procesador (Venta → Settlement)
A4: Vta | B4: Lunes | C4: Martes | D4: Miércoles | E4: Jueves | F4: Viernes | G4: Sábado | H4: Domingo
A5: Setle | B5: Miércoles | C5: Jueves | D5: Viernes | E5: Lunes | F5: Martes | G5: Martes | H5: Martes
A7: Hoy (fecha de corte): | B7: 46216
A8: Nota: cambia la fecha de corte para recalcular Cobrado/Retenido. Las reglas fijan la Fecha de Settlement.
A10: Fecha Venta | B10: Importe Venta | C10: Importe Comisión | D10: Importe Refund | E10: Importe Neto | F10: Día de Venta | G10: Fecha de Settlement | H10: Estado | I10: Importe Retenido | J10: Semana
A11: 46020 | B11: 235269.89 | C11: 5410.34 | D11: 0 | E11: =B11-C11-D11 | F11: =CHOOSE(WEEKDAY(A11,2),"Lunes","Martes","Miércoles","Jueves","Viernes","Sábado","Domingo") | G11: 46022 | H11: =IF(G11<=$B$7,"Cobrado","Retenido") | I11: =IF(H11="Retenido",E11,0) | J11: 2026-W01
A12: 46021 | B12: 206220.49 | C12: 4978.26 | D12: 0 | E12: =B12-C12-D12 | F12: =CHOOSE(WEEKDAY(A12,2),"Lunes","Martes","Miércoles","Jueves","Viernes","Sábado","Domingo") | G12: 46023 | H12: =IF(G12<=$B$7,"Cobrado","Retenido") | I12: =IF(H12="Retenido",E12,0) | J12: 2026-W01
A13: 46022 | B13: 139794.64 | C13: 7229.52 | D13: 0 | E13: =B13-C13-D13 | F13: =CHOOSE(WEEKDAY(A13,2),"Lunes","Martes","Miércoles","Jueves","Viernes","Sábado","Domingo") | G13: 46024 | H13: =IF(G13<=$B$7,"Cobrado","Retenido") | I13: =IF(H13="Retenido",E13,0) | J13: 2026-W01
A14: 46023 | B14: 130209.95 | C14: 0 | D14: 0 | E14: =B14-C14-D14 | F14: =CHOOSE(WEEKDAY(A14,2),"Lunes","Martes","Miércoles","Jueves","Viernes","Sábado","Domingo") | G14: 46027 | H14: =IF(G14<=$B$7,"Cobrado","Retenido") | I14: =IF(H14="Retenido",E14,0) | J14: 2026-W01
A15: 46024 | B15: 242603.6 | C15: 13264.44 | D15: 0 | E15: =B15-C15-D15 | F15: =CHOOSE(WEEKDAY(A15,2),"Lunes","Martes","Miércoles","Jueves","Viernes","Sábado","Domingo") | G15: 46028 | H15: =IF(G15<=$B$7,"Cobrado","Retenido") | I15: =IF(H15="Retenido",E15,0) | J15: 2026-W01
A16: 46025 | B16: 165758.24 | C16: 0 | D16: 0 | E16: =B16-C16-D16 | F16: =CHOOSE(WEEKDAY(A16,2),"Lunes","Martes","Miércoles","Jueves","Viernes","Sábado","Domingo") | G16: 46028 | H16: =IF(G16<=$B$7,"Cobrado","Retenido") | I16: =IF(H16="Retenido",E16,0) | J16: 2026-W01
A17: 46026 | B17: 170851.41 | C17: 0 | D17: 0 | E17: =B17-C17-D17 | F17: =CHOOSE(WEEKDAY(A17,2),"Lunes","Martes","Miércoles","Jueves","Viernes","Sábado","Domingo") | G17: 46028 | H17: =IF(G17<=$B$7,"Cobrado","Retenido") | I17: =IF(H17="Retenido",E17,0) | J17: 2026-W01
A18: 46027 | B18: 285349.81 | C18: 0 | D18: 0 | E18: =B18-C18-D18 | F18: =CHOOSE(WEEKDAY(A18,2),"Lunes","Martes","Miércoles","Jueves","Viernes","Sábado","Domingo") | G18: 46029 | H18: =IF(G18<=$B$7,"Cobrado","Retenido") | I18: =IF(H18="Retenido",E18,0) | J18: 2026-W02
A19: 46028 | B19: 252504.67 | C19: 12345 | D19: 0 | E19: =B19-C19-D19 | F19: =CHOOSE(WEEKDAY(A19,2),"Lunes","Martes","Miércoles","Jueves","Viernes","Sábado","Domingo") | G19: 46030 | H19: =IF(G19<=$B$7,"Cobrado","Retenido") | I19: =IF(H19="Retenido",E19,0) | J19: 2026-W02
A20: 46029 | B20: 347417.91 | C20: 9803.05 | D20: 0 | E20: =B20-C20-D20 | F20: =CHOOSE(WEEKDAY(A20,2),"Lunes","Martes","Miércoles","Jueves","Viernes","Sábado","Domingo") | G20: 46031 | H20: =IF(G20<=$B$7,"Cobrado","Retenido") | I20: =IF(H20="Retenido",E20,0) | J20: 2026-W02
A21: 46030 | B21: 293544.34 | C21: 5592.97 | D21: 0 | E21: =B21-C21-D21 | F21: =CHOOSE(WEEKDAY(A21,2),"Lunes","Martes","Miércoles","Jueves","Viernes","Sábado","Domingo") | G21: 46034 | H21: =IF(G21<=$B$7,"Cobrado","Retenido") | I21: =IF(H21="Retenido",E21,0) | J21: 2026-W02
A22: 46031 | B22: 324487.78 | C22: 8164.67 | D22: 0 | E22: =B22-C22-D22 | F22: =CHOOSE(WEEKDAY(A22,2),"Lunes","Martes","Miércoles","Jueves","Viernes","Sábado","Domingo") | G22: 46035 | H22: =IF(G22<=$B$7,"Cobrado","Retenido") | I22: =IF(H22="Retenido",E22,0) | J22: 2026-W02
... A207: 46216 | B207: 1064905.9 | C207: 0 | D207: 0 | E207: =B207-C207-D207 | F207: =CHOOSE(WEEKDAY(A207,2),"Lunes","Martes","Miércoles","Jueves","Viernes","Sábado","Domingo") | G207: 46218 | H207: =IF(G207<=$B$7,"Cobrado","Retenido") | I207: =IF(H207="Retenido",E207,0) | J207: 2026-W29
A208: TOTAL | B208: =SUM(B11:B207) | C208: =SUM(C11:C207) | D208: =SUM(D11:D207) | E208: =SUM(E11:E207) | I208: =SUM(I11:I207)

Sheet Nuvei
A1: CALCULADORA DE COBROS — NUVEI
A3: Reglas del procesador (Venta → Settlement)
A4: Vta | B4: Lunes | C4: Martes | D4: Miércoles | E4: Jueves | F4: Viernes | G4: Sábado | H4: Domingo
A5: Setle | B5: Viernes | C5: Lunes | D5: Martes | E5: Miércoles | F5: Jueves | G5: Viernes | H5: Viernes
A7: Hoy (fecha de corte): | B7: 46216
A8: Nota: cambia la fecha de corte para recalcular Cobrado/Retenido. Las reglas fijan la Fecha de Settlement.
A10: Fecha Venta | B10: Importe Venta | C10: Importe Comisión | D10: Importe Refund | E10: Importe Neto | F10: Día de Venta | G10: Fecha de Settlement | H10: Estado | I10: Importe Retenido | J10: Semana
A11: 45922 | B11: -33.65 | C11: 0.41 | D11: 0 | E11: =B11-C11-D11 | F11: =CHOOSE(WEEKDAY(A11,2),"Lunes","Martes","Miércoles","Jueves","Viernes","Sábado","Domingo") | G11: 45926 | H11: =IF(G11<=$B$7,"Cobrado","Retenido") | I11: =IF(H11="Retenido",E11,0) | J11: 2025-W39
A12: 45923 | B12: 56839.02 | C12: 788.65 | D12: 0 | E12: =B12-C12-D12 | F12: =CHOOSE(WEEKDAY(A12,2),"Lunes","Martes","Miércoles","Jueves","Viernes","Sábado","Domingo") | G12: 45929 | H12: =IF(G12<=$B$7,"Cobrado","Retenido") | I12: =IF(H12="Retenido",E12,0) | J12: 2025-W39
A13: 45924 | B13: 48289.18 | C13: 567.44 | D13: 0 | E13: =B13-C13-D13 | F13: =CHOOSE(WEEKDAY(A13,2),"Lunes","Martes","Miércoles","Jueves","Viernes","Sábado","Domingo") | G13: 45930 | H13: =IF(G13<=$B$7,"Cobrado","Retenido") | I13: =IF(H13="Retenido",E13,0) | J13: 2025-W39
A14: 45925 | B14: 235902.11 | C14: 2725.3 | D14: 0 | E14: =B14-C14-D14 | F14: =CHOOSE(WEEKDAY(A14,2),"Lunes","Martes","Miércoles","Jueves","Viernes","Sábado","Domingo") | G14: 45931 | H14: =IF(G14<=$B$7,"Cobrado","Retenido") | I14: =IF(H14="Retenido",E14,0) | J14: 2025-W39
A15: 45926 | B15: 299469.68 | C15: 3652.83 | D15: 0 | E15: =B15-C15-D15 | F15: =CHOOSE(WEEKDAY(A15,2),"Lunes","Martes","Miércoles","Jueves","Viernes","Sábado","Domingo") | G15: 45932 | H15: =IF(G15<=$B$7,"Cobrado","Retenido") | I15: =IF(H15="Retenido",E15,0) | J15: 2025-W39
A16: 45927 | B16: 249544.46 | C16: 2763 | D16: 0 | E16: =B16-C16-D16 | F16: =CHOOSE(WEEKDAY(A16,2),"Lunes","Martes","Miércoles","Jueves","Viernes","Sábado","Domingo") | G16: 45933 | H16: =IF(G16<=$B$7,"Cobrado","Retenido") | I16: =IF(H16="Retenido",E16,0) | J16: 2025-W39
A17: 45928 | B17: 330552.59 | C17: 3529.85 | D17: 0 | E17: =B17-C17-D17 | F17: =CHOOSE(WEEKDAY(A17,2),"Lunes","Martes","Miércoles","Jueves","Viernes","Sábado","Domingo") | G17: 45933 | H17: =IF(G17<=$B$7,"Cobrado","Retenido") | I17: =IF(H17="Retenido",E17,0) | J17: 2025-W39
A18: 45929 | B18: 356898.85 | C18: 4197.91 | D18: 0 | E18: =B18-C18-D18 | F18: =CHOOSE(WEEKDAY(A18,2),"Lunes","Martes","Miércoles","Jueves","Viernes","Sábado","Domingo") | G18: 45933 | H18: =IF(G18<=$B$7,"Cobrado","Retenido") | I18: =IF(H18="Retenido",E18,0) | J18: 2025-W40
A19: 45930 | B19: 380391.93 | C19: 5281.08 | D19: 0 | E19: =B19-C19-D19 | F19: =CHOOSE(WEEKDAY(A19,2),"Lunes","Martes","Miércoles","Jueves","Viernes","Sábado","Domingo") | G19: 45936 | H19: =IF(G19<=$B$7,"Cobrado","Retenido") | I19: =IF(H19="Retenido",E19,0) | J19: 2025-W40
A20: 45931 | B20: 472384.54 | C20: 5916.07 | D20: 0 | E20: =B20-C20-D20 | F20: =CHOOSE(WEEKDAY(A20,2),"Lunes","Martes","Miércoles","Jueves","Viernes","Sábado","Domingo") | G20: 45937 | H20: =IF(G20<=$B$7,"Cobrado","Retenido") | I20: =IF(H20="Retenido",E20,0) | J20: 2025-W40
A21: 45932 | B21: 405681.66 | C21: 5213.26 | D21: 0 | E21: =B21-C21-D21 | F21: =CHOOSE(WEEKDAY(A21,2),"Lunes","Martes","Miércoles","Jueves","Viernes","Sábado","Domingo") | G21: 45938 | H21: =IF(G21<=$B$7,"Cobrado","Retenido") | I21: =IF(H21="Retenido",E21,0) | J21: 2025-W40
A22: 45933 | B22: 363218.41 | C22: 4542.18 | D22: 0 | E22: =B22-C22-D22 | F22: =CHOOSE(WEEKDAY(A22,2),"Lunes","Martes","Miércoles","Jueves","Viernes","Sábado","Domingo") | G22: 45939 | H22: =IF(G22<=$B$7,"Cobrado","Retenido") | I22: =IF(H22="Retenido",E22,0) | J22: 2025-W40
... A296: 46215 | B296: 355104.7 | C296: 8495.04 | D296: 0 | E296: =B296-C296-D296 | F296: =CHOOSE(WEEKDAY(A296,2),"Lunes","Martes","Miércoles","Jueves","Viernes","Sábado","Domingo") | G296: 46220 | H296: =IF(G296<=$B$7,"Cobrado","Retenido") | I296: =IF(H296="Retenido",E296,0) | J296: 2026-W28
A297: TOTAL | B297: =SUM(B11:B296) | C297: =SUM(C11:C296) | D297: =SUM(D11:D296) | E297: =SUM(E11:E296) | I297: =SUM(I11:I296)

Sheet Shift4
A1: CALCULADORA DE COBROS — SHIFT4
A3: Reglas del procesador (Venta → Settlement)
A4: Vta | B4: Lunes | C4: Martes | D4: Miércoles | E4: Jueves | F4: Viernes | G4: Sábado | H4: Domingo
A5: Setle | B5: Jueves | C5: Viernes | D5: Lunes | E5: Martes | F5: Miércoles | G5: Miércoles | H5: Miércoles
A7: Hoy (fecha de corte): | B7: 46216
A8: Nota: cambia la fecha de corte para recalcular Cobrado/Retenido. Las reglas fijan la Fecha de Settlement.
A10: Fecha Venta | B10: Importe Venta | C10: Importe Comisión | D10: Importe Refund | E10: Importe Neto | F10: Día de Venta | G10: Fecha de Settlement | H10: Estado | I10: Importe Retenido | J10: Semana
A11: 46111 | B11: 289542.93 | C11: 3657.81 | D11: 0 | E11: =B11-C11-D11 | F11: =CHOOSE(WEEKDAY(A11,2),"Lunes","Martes","Miércoles","Jueves","Viernes","Sábado","Domingo") | G11: 46114 | H11: =IF(G11<=$B$7,"Cobrado","Retenido") | I11: =IF(H11="Retenido",E11,0) | J11: 2026-W14
A12: 46112 | B12: 454942.28 | C12: 5819.32 | D12: 0 | E12: =B12-C12-D12 | F12: =CHOOSE(WEEKDAY(A12,2),"Lunes","Martes","Miércoles","Jueves","Viernes","Sábado","Domingo") | G12: 46115 | H12: =IF(G12<=$B$7,"Cobrado","Retenido") | I12: =IF(H12="Retenido",E12,0) | J12: 2026-W14
A13: 46113 | B13: 664964.82 | C13: 7493.08 | D13: 0 | E13: =B13-C13-D13 | F13: =CHOOSE(WEEKDAY(A13,2),"Lunes","Martes","Miércoles","Jueves","Viernes","Sábado","Domingo") | G13: 46118 | H13: =IF(G13<=$B$7,"Cobrado","Retenido") | I13: =IF(H13="Retenido",E13,0) | J13: 2026-W14
A14: 46114 | B14: 579089.9 | C14: 6416.15 | D14: 0 | E14: =B14-C14-D14 | F14: =CHOOSE(WEEKDAY(A14,2),"Lunes","Martes","Miércoles","Jueves","Viernes","Sábado","Domingo") | G14: 46119 | H14: =IF(G14<=$B$7,"Cobrado","Retenido") | I14: =IF(H14="Retenido",E14,0) | J14: 2026-W14
A15: 46115 | B15: 483670.16 | C15: 6028.77 | D15: 0 | E15: =B15-C15-D15 | F15: =CHOOSE(WEEKDAY(A15,2),"Lunes","Martes","Miércoles","Jueves","Viernes","Sábado","Domingo") | G15: 46120 | H15: =IF(G15<=$B$7,"Cobrado","Retenido") | I15: =IF(H15="Retenido",E15,0) | J15: 2026-W14
A16: 46116 | B16: 377860.65 | C16: 4215.53 | D16: 0 | E16: =B16-C16-D16 | F16: =CHOOSE(WEEKDAY(A16,2),"Lunes","Martes","Miércoles","Jueves","Viernes","Sábado","Domingo") | G16: 46120 | H16: =IF(G16<=$B$7,"Cobrado","Retenido") | I16: =IF(H16="Retenido",E16,0) | J16: 2026-W14
A17: 46117 | B17: 408096.3 | C17: 4523.94 | D17: 0 | E17: =B17-C17-D17 | F17: =CHOOSE(WEEKDAY(A17,2),"Lunes","Martes","Miércoles","Jueves","Viernes","Sábado","Domingo") | G17: 46120 | H17: =IF(G17<=$B$7,"Cobrado","Retenido") | I17: =IF(H17="Retenido",E17,0) | J17: 2026-W14
A18: 46118 | B18: 523324.71 | C18: 5661.1 | D18: 0 | E18: =B18-C18-D18 | F18: =CHOOSE(WEEKDAY(A18,2),"Lunes","Martes","Miércoles","Jueves","Viernes","Sábado","Domingo") | G18: 46121 | H18: =IF(G18<=$B$7,"Cobrado","Retenido") | I18: =IF(H18="Retenido",E18,0) | J18: 2026-W15
A19: 46119 | B19: 560218.53 | C19: 6183.08 | D19: 0 | E19: =B19-C19-D19 | F19: =CHOOSE(WEEKDAY(A19,2),"Lunes","Martes","Miércoles","Jueves","Viernes","Sábado","Domingo") | G19: 46122 | H19: =IF(G19<=$B$7,"Cobrado","Retenido") | I19: =IF(H19="Retenido",E19,0) | J19: 2026-W15
A20: 46120 | B20: 589642.69 | C20: 6705.74 | D20: 0 | E20: =B20-C20-D20 | F20: =CHOOSE(WEEKDAY(A20,2),"Lunes","Martes","Miércoles","Jueves","Viernes","Sábado","Domingo") | G20: 46125 | H20: =IF(G20<=$B$7,"Cobrado","Retenido") | I20: =IF(H20="Retenido",E20,0) | J20: 2026-W15
A21: 46121 | B21: 611628.24 | C21: 6600.68 | D21: 0 | E21: =B21-C21-D21 | F21: =CHOOSE(WEEKDAY(A21,2),"Lunes","Martes","Miércoles","Jueves","Viernes","Sábado","Domingo") | G21: 46126 | H21: =IF(G21<=$B$7,"Cobrado","Retenido") | I21: =IF(H21="Retenido",E21,0) | J21: 2026-W15
A22: 46122 | B22: 626036.02 | C22: 7254.71 | D22: 0 | E22: =B22-C22-D22 | F22: =CHOOSE(WEEKDAY(A22,2),"Lunes","Martes","Miércoles","Jueves","Viernes","Sábado","Domingo") | G22: 46127 | H22: =IF(G22<=$B$7,"Cobrado","Retenido") | I22: =IF(H22="Retenido",E22,0) | J22: 2026-W15
... A116: 46216 | B116: 314504.37 | C116: 3789.68 | D116: 0 | E116: =B116-C116-D116 | F116: =CHOOSE(WEEKDAY(A116,2),"Lunes","Martes","Miércoles","Jueves","Viernes","Sábado","Domingo") | G116: 46219 | H116: =IF(G116<=$B$7,"Cobrado","Retenido") | I116: =IF(H116="Retenido",E116,0) | J116: 2026-W29
A117: TOTAL | B117: =SUM(B11:B116) | C117: =SUM(C11:C116) | D117: =SUM(D11:D116) | E117: =SUM(E11:E116) | I117: =SUM(I11:I116)

Sheet Paysafe
A1: CALCULADORA DE COBROS — PAYSAFE
A3: Reglas del procesador (Venta → Settlement)
A4: Vta | B4: Lunes | C4: Martes | D4: Miércoles | E4: Jueves | F4: Viernes | G4: Sábado | H4: Domingo
A5: Setle | B5: Miércoles | C5: Jueves | D5: Viernes | E5: Lunes | F5: Martes | G5: Martes | H5: Martes
A7: Hoy (fecha de corte): | B7: 46216
A8: Nota: cambia la fecha de corte para recalcular Cobrado/Retenido. Las reglas fijan la Fecha de Settlement.
A10: Fecha Venta | B10: Importe Venta | C10: Importe Comisión | D10: Importe Refund | E10: Importe Neto | F10: Día de Venta | G10: Fecha de Settlement | H10: Estado | I10: Importe Retenido | J10: Semana
A11: 46199 | B11: 1092.16 | C11: 0 | D11: 0 | E11: =B11-C11-D11 | F11: =CHOOSE(WEEKDAY(A11,2),"Lunes","Martes","Miércoles","Jueves","Viernes","Sábado","Domingo") | G11: 46203 | H11: =IF(G11<=$B$7,"Cobrado","Retenido") | I11: =IF(H11="Retenido",E11,0) | J11: 2026-W26
A12: 46202 | B12: 0 | C12: 15.27 | D12: 116.67 | E12: =B12-C12-D12 | F12: =CHOOSE(WEEKDAY(A12,2),"Lunes","Martes","Miércoles","Jueves","Viernes","Sábado","Domingo") | G12: 46204 | H12: =IF(G12<=$B$7,"Cobrado","Retenido") | I12: =IF(H12="Retenido",E12,0) | J12: 2026-W27
A13: 46203 | B13: 1249.39 | C13: 0 | D13: 0 | E13: =B13-C13-D13 | F13: =CHOOSE(WEEKDAY(A13,2),"Lunes","Martes","Miércoles","Jueves","Viernes","Sábado","Domingo") | G13: 46205 | H13: =IF(G13<=$B$7,"Cobrado","Retenido") | I13: =IF(H13="Retenido",E13,0) | J13: 2026-W27
A14: 46204 | B14: 96284.78 | C14: 0 | D14: 102.79 | E14: =B14-C14-D14 | F14: =CHOOSE(WEEKDAY(A14,2),"Lunes","Martes","Miércoles","Jueves","Viernes","Sábado","Domingo") | G14: 46206 | H14: =IF(G14<=$B$7,"Cobrado","Retenido") | I14: =IF(H14="Retenido",E14,0) | J14: 2026-W27
A15: 46205 | B15: 162611.9 | C15: 20.94 | D15: 0 | E15: =B15-C15-D15 | F15: =CHOOSE(WEEKDAY(A15,2),"Lunes","Martes","Miércoles","Jueves","Viernes","Sábado","Domingo") | G15: 46209 | H15: =IF(G15<=$B$7,"Cobrado","Retenido") | I15: =IF(H15="Retenido",E15,0) | J15: 2026-W27
A16: 46206 | B16: 149702.38 | C16: 1579.37 | D16: 300.06 | E16: =B16-C16-D16 | F16: =CHOOSE(WEEKDAY(A16,2),"Lunes","Martes","Miércoles","Jueves","Viernes","Sábado","Domingo") | G16: 46210 | H16: =IF(G16<=$B$7,"Cobrado","Retenido") | I16: =IF(H16="Retenido",E16,0) | J16: 2026-W27
A17: 46207 | B17: 125391.42 | C17: 0 | D17: 0 | E17: =B17-C17-D17 | F17: =CHOOSE(WEEKDAY(A17,2),"Lunes","Martes","Miércoles","Jueves","Viernes","Sábado","Domingo") | G17: 46210 | H17: =IF(G17<=$B$7,"Cobrado","Retenido") | I17: =IF(H17="Retenido",E17,0) | J17: 2026-W27
A18: 46208 | B18: 145271.71 | C18: 0 | D18: 282.93 | E18: =B18-C18-D18 | F18: =CHOOSE(WEEKDAY(A18,2),"Lunes","Martes","Miércoles","Jueves","Viernes","Sábado","Domingo") | G18: 46210 | H18: =IF(G18<=$B$7,"Cobrado","Retenido") | I18: =IF(H18="Retenido",E18,0) | J18: 2026-W27
A19: 46209 | B19: 177639.11 | C19: 7132.19 | D19: 1935.38 | E19: =B19-C19-D19 | F19: =CHOOSE(WEEKDAY(A19,2),"Lunes","Martes","Miércoles","Jueves","Viernes","Sábado","Domingo") | G19: 46211 | H19: =IF(G19<=$B$7,"Cobrado","Retenido") | I19: =IF(H19="Retenido",E19,0) | J19: 2026-W28
A20: 46210 | B20: 176573.66 | C20: 2365.5 | D20: 270.23 | E20: =B20-C20-D20 | F20: =CHOOSE(WEEKDAY(A20,2),"Lunes","Martes","Miércoles","Jueves","Viernes","Sábado","Domingo") | G20: 46212 | H20: =IF(G20<=$B$7,"Cobrado","Retenido") | I20: =IF(H20="Retenido",E20,0) | J20: 2026-W28
A21: 46211 | B21: 174256.68 | C21: 3164.89 | D21: 856.97 | E21: =B21-C21-D21 | F21: =CHOOSE(WEEKDAY(A21,2),"Lunes","Martes","Miércoles","Jueves","Viernes","Sábado","Domingo") | G21: 46213 | H21: =IF(G21<=$B$7,"Cobrado","Retenido") | I21: =IF(H21="Retenido",E21,0) | J21: 2026-W28
A22: 46212 | B22: 162941.51 | C22: 2872.93 | D22: 1044.11 | E22: =B22-C22-D22 | F22: =CHOOSE(WEEKDAY(A22,2),"Lunes","Martes","Miércoles","Jueves","Viernes","Sábado","Domingo") | G22: 46216 | H22: =IF(G22<=$B$7,"Cobrado","Retenido") | I22: =IF(H22="Retenido",E22,0) | J22: 2026-W28
... A44: 46234 | B44: 0 | C44: 0 | D44: 0 | E44: =B44-C44-D44 | F44: =CHOOSE(WEEKDAY(A44,2),"Lunes","Martes","Miércoles","Jueves","Viernes","Sábado","Domingo") | G44: 46238 | H44: =IF(G44<=$B$7,"Cobrado","Retenido") | I44: =IF(H44="Retenido",E44,0) | J44: 2026-W31
A45: TOTAL | B45: =SUM(B11:B44) | C45: =SUM(C11:C44) | D45: =SUM(D11:D44) | E45: =SUM(E11:E44) | I45: =SUM(I11:I44)
